<?xml version="1.0"?>
<!-- Arakno v.1 - Created by Anto" -->
  <robot name="arakno">

    <link name="BL_lowerleg">
      <inertial>
        <origin xyz="0 0 0" rpy="0 0 0"/>
        <mass value="2.9"/>
        <inertia ixx="0.0166" ixy="0" ixz="0" iyy="0.0166" iyz="0" izz="0.0031"/>
      </inertial>
      <visual>
        <origin xyz="-0.125 0 0" rpy="0 -1.5708 0"/>
        <geometry>
          <mesh filename="package://resources/meshes/stl/BL_lowerleg.stl" scale="1.0 1.0 1.0"/>
        </geometry>
        <material name="lowerleg"/>
      </visual>
      <collision>
        <origin xyz="-0.125 0 0" rpy="0 -1.5708 0"/>
        <geometry>
          <mesh filename="package://resources/meshes/stl/BL_lowerleg.stl" scale="1.0 1.0 1.0"/>
        </geometry>
      </collision>
    </link>

    <link name="BL_shoulder">
      <inertial>
        <origin xyz="0 0 0" rpy="0 0 0"/>
        <mass value="0.13"/>
        <inertia ixx="0.00007" ixy="0" ixz="0" iyy="0.00007" iyz="0" izz="0.00014"/>
      </inertial>
      <visual>
        <origin xyz="0 0 0" rpy="1.5708 0 0"/>
        <geometry>
          <mesh filename="package://resources/meshes/stl/BL_shoulder.stl" scale="1.0 1.0 1.0"/>
        </geometry>
        <material name="shoulder"/>
      </visual>
      <collision>
        <origin xyz="0 0 0" rpy="1.5708 0 0"/>
        <geometry>
          <mesh filename="package://resources/meshes/stl/BL_shoulder.stl" scale="1.0 1.0 1.0"/>
        </geometry>
      </collision>
    </link>

    <link name="BL_upperleg">
      <inertial>
        <origin xyz="0 0 0" rpy="0 0 0"/>
        <mass value="2.7"/>
        <inertia ixx="0.0105" ixy="0" ixz="0" iyy="0.0105" iyz="0" izz="0.0028"/>
      </inertial>
      <visual>
        <origin xyz="-0.1 0 0" rpy="0 -1.5708 0"/>
        <geometry>
          <mesh filename="package://resources/meshes/stl/BL_upperleg.stl" scale="1.0 1.0 1.0"/>
        </geometry>
        <material name="upperleg"/>
      </visual>
      <collision>
        <origin xyz="-0.1 0 0" rpy="0 -1.5708 0"/>
        <geometry>
          <mesh filename="package://resources/meshes/stl/BL_upperleg.stl" scale="1.0 1.0 1.0"/>
        </geometry>
      </collision>
    </link>

    <link name="BR_lowerleg">
      <inertial>
        <origin xyz="0 0 0" rpy="0 0 0"/>
        <mass value="2.9"/>
        <inertia ixx="0.0166" ixy="0" ixz="0" iyy="0.0166" iyz="0" izz="0.0031"/>
      </inertial>
      <visual>
        <origin xyz="-0.125 0 0" rpy="0 -1.5708 0"/>
        <geometry>
          <mesh filename="package://resources/meshes/stl/BR_lowerleg.stl" scale="1.0 1.0 1.0"/>
        </geometry>
        <material name="lowerleg"/>
      </visual>
      <collision>
        <origin xyz="-0.125 0 0" rpy="0 -1.5708 0"/>
        <geometry>
          <mesh filename="package://resources/meshes/stl/BR_lowerleg.stl" scale="1.0 1.0 1.0"/>
        </geometry>
      </collision>
    </link>

    <link name="BR_shoulder">
      <inertial>
        <origin xyz="0 0 0" rpy="0 0 0"/>
        <mass value="0.13"/>
        <inertia ixx="0.00007" ixy="0" ixz="0" iyy="0.00007" iyz="0" izz="0.00014"/>
      </inertial>
      <visual>
        <origin xyz="0 0 0" rpy="1.5708 0 0"/>
        <geometry>
          <mesh filename="package://resources/meshes/stl/BR_shoulder.stl" scale="1.0 1.0 1.0"/>
        </geometry>
        <material name="shoulder"/>
      </visual>
      <collision>
        <origin xyz="0 0 0" rpy="1.5708 0 0"/>
        <geometry>
          <mesh filename="package://resources/meshes/stl/BR_shoulder.stl" scale="1.0 1.0 1.0"/>
        </geometry>
      </collision>
    </link>

    <link name="BR_upperleg">
      <inertial>
        <origin xyz="0 0 0" rpy="0 0 0"/>
        <mass value="2.7"/>
        <inertia ixx="0.0105" ixy="0" ixz="0" iyy="0.0105" iyz="0" izz="0.0028"/>
      </inertial>
      <visual>
        <origin xyz="-0.1 0 0" rpy="0 -1.5708 0"/>
        <geometry>
          <mesh filename="package://resources/meshes/stl/BR_upperleg.stl" scale="1.0 1.0 1.0"/>
        </geometry>
        <material name="upperleg"/>
      </visual>
      <collision>
        <origin xyz="-0.1 0 0" rpy="0 -1.5708 0"/>
        <geometry>
          <mesh filename="package://resources/meshes/stl/BR_upperleg.stl" scale="1.0 1.0 1.0"/>
        </geometry>
      </collision>
    </link>

    <link name="FL_lowerleg">
      <inertial>
        <origin xyz="0 0 0" rpy="0 0 0"/>
        <mass value="2.9"/>
        <inertia ixx="0.0166" ixy="0" ixz="0" iyy="0.0166" iyz="0" izz="0.0031"/>
      </inertial>
      <visual>
        <origin xyz="-0.125 0 0" rpy="0 -1.5708 0"/>
        <geometry>
          <mesh filename="package://resources/meshes/stl/FL_lowerleg.stl" scale="1.0 1.0 1.0"/>
        </geometry>
        <material name="lowerleg"/>
      </visual>
      <collision>
        <origin xyz="-0.125 0 0" rpy="0 -1.5708 0"/>
        <geometry>
          <mesh filename="package://resources/meshes/stl/FL_lowerleg.stl" scale="1.0 1.0 1.0"/>
        </geometry>
      </collision>
    </link>

    <link name="FL_shoulder">
      <inertial>
        <origin xyz="0 0 0" rpy="0 0 0"/>
        <mass value="0.13"/>
        <inertia ixx="0.00007" ixy="0" ixz="0" iyy="0.00007" iyz="0" izz="0.00014"/>
      </inertial>
      <visual>
        <origin xyz="0 0 0" rpy="1.5708 0 0"/>
        <geometry>
          <mesh filename="package://resources/meshes/stl/FL_shoulder.stl" scale="1.0 1.0 1.0"/>
        </geometry>
        <material name="shoulder"/>
      </visual>
      <collision>
        <origin xyz="0 0 0" rpy="1.5708 0 0"/>
        <geometry>
          <mesh filename="package://resources/meshes/stl/FL_shoulder.stl" scale="1.0 1.0 1.0"/>
        </geometry>
      </collision>
    </link>

    <link name="FL_upperleg">
      <inertial>
        <origin xyz="0 0 0" rpy="0 0 0"/>
        <mass value="2.7"/>
        <inertia ixx="0.0105" ixy="0" ixz="0" iyy="0.0105" iyz="0" izz="0.0028"/>
      </inertial>
      <visual>
        <origin xyz="-0.1 0 0" rpy="0 -1.5708 0"/>
        <geometry>
          <mesh filename="package://resources/meshes/stl/FL_upperleg.stl" scale="1.0 1.0 1.0"/>
        </geometry>
        <material name="upperleg"/>
      </visual>
      <collision>
        <origin xyz="-0.1 0 0" rpy="0 -1.5708 0"/>
        <geometry>
          <mesh filename="package://resources/meshes/stl/FL_upperleg.stl" scale="1.0 1.0 1.0"/>
        </geometry>
      </collision>
    </link>

    <link name="FR_lowerleg">
      <inertial>
        <origin xyz="0 0 0" rpy="0 0 0"/>
        <mass value="2.9"/>
        <inertia ixx="0.0166" ixy="0" ixz="0" iyy="0.0166" iyz="0" izz="0.0031"/>
      </inertial>
      <visual>
        <origin xyz="-0.125 0 0" rpy="0 -1.5708 0"/>
        <geometry>
          <mesh filename="package://resources/meshes/stl/FR_lowerleg.stl" scale="1.0 1.0 1.0"/>
        </geometry>
        <material name="lowerleg"/>
      </visual>
      <collision>
        <origin xyz="-0.125 0 0" rpy="0 -1.5708 0"/>
        <geometry>
          <mesh filename="package://resources/meshes/stl/FR_lowerleg.stl" scale="1.0 1.0 1.0"/>
        </geometry>
      </collision>
    </link>

    <link name="FR_shoulder">
      <inertial>
        <origin xyz="0 0 0" rpy="0 0 0"/>
        <mass value="0.13"/>
        <inertia ixx="0.00007" ixy="0" ixz="0" iyy="0.00007" iyz="0" izz="0.00014"/>
      </inertial>
      <visual>
        <origin xyz="0 0 0" rpy="1.5708 0 0"/>
        <geometry>
          <mesh filename="package://resources/meshes/stl/FR_shoulder.stl" scale="1.0 1.0 1.0"/>
        </geometry>
        <material name="shoulder"/>
      </visual>
      <collision>
        <origin xyz="0 0 0" rpy="1.5708 0 0"/>
        <geometry>
          <mesh filename="package://resources/meshes/stl/FR_shoulder.stl" scale="1.0 1.0 1.0"/>
        </geometry>
      </collision>
    </link>

    <link name="FR_upperleg">
      <inertial>
        <origin xyz="0 0 0" rpy="0 0 0"/>
        <mass value="2.7"/>
        <inertia ixx="0.0105" ixy="0" ixz="0" iyy="0.0105" iyz="0" izz="0.0028"/>
      </inertial>
      <visual>
        <origin xyz="-0.1 0 0" rpy="0 -1.5708 0"/>
        <geometry>
          <mesh filename="package://resources/meshes/stl/FR_upperleg.stl" scale="1.0 1.0 1.0"/>
        </geometry>
        <material name="upperleg"/>
      </visual>
      <collision>
        <origin xyz="-0.1 0 0" rpy="0 -1.5708 0"/>
        <geometry>
          <mesh filename="package://resources/meshes/stl/FR_upperleg.stl" scale="1.0 1.0 1.0"/>
        </geometry>
      </collision>
    </link>

    <!--<link name="camera">
      <visual>
        <origin xyz="0 0 0" rpy="0 -1.5708 0"/>
        <geometry>
          <mesh filename="package://resources/meshes/stl/camera.stl" scale="1.0 1.0 1.0"/>
        </geometry>
        <material name="camera"/>
      </visual>
      <collision>
        <origin xyz="0 0 0" rpy="0 -1.5708 0"/>
        <geometry>
          <mesh filename="package://resources/meshes/stl/camera.stl" scale="1.0 1.0 1.0"/>
        </geometry>
      </collision>
    </link>-->

    <link name="trunk">
      <inertial>
        <origin xyz="0 0 0" rpy="0 0 0"/>
        <mass value="25.0"/>
        <inertia ixx="0.207" ixy="0" ixz="0" iyy="0.207" iyz="0" izz="0.32"/>
      </inertial>
      <visual>
        <origin xyz="0 0 0" rpy="0 0 0"/>
        <geometry>
          <mesh filename="package://resources/meshes/stl/trunk.stl" scale="1.0 1.0 1.0"/>
        </geometry>
        <material name="trunk"/>
      </visual>
      <collision>
        <origin xyz="0 0 0" rpy="0 0 0"/>
        <geometry>
          <mesh filename="package://resources/meshes/stl/trunk.stl" scale="1.0 1.0 1.0"/>
        </geometry>
      </collision>
    </link>

    <joint name="BL_lowerleg_joint" type="revolute">
      <origin xyz="-0.2 0 0" rpy="0 0 0"/>
      <parent link="BL_upperleg"/>
      <child link="BL_lowerleg"/>
      <axis xyz="0 0 1.0"/>
      <limit lower="0.05" upper="1.08" effort="30" velocity="5"/>
    </joint>

    <joint name="BL_shoulder_joint" type="revolute">
      <origin xyz="-0.10153 -0.10153 0" rpy="0 0 -0.7854"/>
      <parent link="trunk"/>
      <child link="BL_shoulder"/>
      <axis xyz="0 0 1.0"/>
      <limit lower="-0.785" upper="0.785" effort="30" velocity="5"/>
    </joint>

    <joint name="BL_upperleg_joint" type="revolute">
      <origin xyz="0 -0.005 0" rpy="1.5708 0 1.5708"/>
      <parent link="BL_shoulder"/>
      <child link="BL_upperleg"/>
      <axis xyz="0 0 1.0"/>
      <limit lower="-0.785" upper="0.785" effort="30" velocity="5"/>
    </joint>

    <joint name="BR_lowerleg_joint" type="revolute">
      <origin xyz="-0.2 0 0" rpy="0 0 0"/>
      <parent link="BR_upperleg"/>
      <child link="BR_lowerleg"/>
      <axis xyz="0 0 1.0"/>
      <limit lower="0.05" upper="1.08" effort="30" velocity="5"/>
    </joint>

    <joint name="BR_shoulder_joint" type="revolute">
      <origin xyz="0.10153 -0.10153 0" rpy="0 0 0.7854"/>
      <parent link="trunk"/>
      <child link="BR_shoulder"/>
      <axis xyz="0 0 1.0"/>
      <limit lower="-0.785" upper="0.785" effort="30" velocity="5"/>
    </joint>

    <joint name="BR_upperleg_joint" type="revolute">
      <origin xyz="0 -0.005 0" rpy="1.5708 0 1.5708"/>
      <parent link="BR_shoulder"/>
      <child link="BR_upperleg"/>
      <axis xyz="0 0 1.0"/>
      <limit lower="-0.785" upper="0.785" effort="30" velocity="5"/>
    </joint>

    <joint name="FL_lowerleg_joint" type="revolute">
      <origin xyz="-0.2 0 0" rpy="0 0 0"/>
      <parent link="FL_upperleg"/>
      <child link="FL_lowerleg"/>
      <axis xyz="0 0 1.0"/>
      <limit lower="0.05" upper="1.08" effort="30" velocity="5"/>
    </joint>

    <joint name="FL_shoulder_joint" type="revolute">
      <origin xyz="-0.10153 0.10153 0" rpy="0 0 -2.35619"/>
      <parent link="trunk"/>
      <child link="FL_shoulder"/>
      <axis xyz="0 0 1.0"/>
      <limit lower="-0.785" upper="0.785" effort="30" velocity="5"/>
    </joint>

    <joint name="FL_upperleg_joint" type="revolute">
      <origin xyz="0 -0.005 0" rpy="1.5708 0 1.5708"/>
      <parent link="FL_shoulder"/>
      <child link="FL_upperleg"/>
      <axis xyz="0 0 1.0"/>
      <limit lower="-0.785" upper="0.785" effort="30" velocity="5"/>
    </joint>

    <joint name="FR_lowerleg_joint" type="revolute">
      <origin xyz="-0.2 0 0" rpy="0 0 0"/>
      <parent link="FR_upperleg"/>
      <child link="FR_lowerleg"/>
      <axis xyz="0 0 1.0"/>
      <limit lower="0.05" upper="1.08" effort="30" velocity="5"/>
    </joint>

    <joint name="FR_shoulder_joint" type="revolute">
      <origin xyz="0.10153 0.10153 0" rpy="0 0 2.35619"/>
      <parent link="trunk"/>
      <child link="FR_shoulder"/>
      <axis xyz="0 0 1.0"/>
      <limit lower="-0.785" upper="0.785" effort="30" velocity="5"/>
    </joint>

    <joint name="FR_upperleg_joint" type="revolute">
      <origin xyz="0 -0.005 0" rpy="1.5708 0 1.5708"/>
      <parent link="FR_shoulder"/>
      <child link="FR_upperleg"/>
      <axis xyz="0 0 1.0"/>
      <limit lower="-0.785" upper="0.785" effort="30" velocity="5"/>
    </joint>

    <!--<joint name="camera_joint" type="revolute">
      <origin xyz="0 0.14358 0" rpy="1.5708 0 -1.5708"/>
      <parent link="trunk"/>
      <child link="camera"/>
      <axis xyz="0 0 1.0"/>
      <limit lower="-0.785" upper="0.785" effort="30" velocity="5"/>
    </joint>

    <material name="camera">
      <color rgba="0.637597 0.066626 0.104617 1.0"/>
    </material>-->

    <material name="lowerleg">
      <color rgba="0.597202 0.48515 0.391573 1.0"/>
    </material>

    <material name="shoulder">
      <color rgba="0.846874 0.423268 0.066626 1.0"/>
    </material>

    <material name="trunk">
      <color rgba="0.003347 0.078187 0.14996 1.0"/>
    </material>

    <material name="upperleg">
      <color rgba="0.006995 0.107023 0.341914 1.0"/>
    </material>

  </robot>
